Traceback (most recent call last):
  File "D:\Users\Cathmoelic\AppData\Local\Programs\Python\Python39\lib\site-packages\jupyter_cache\executors\utils.py", line 51, in single_nb_execution
    executenb(
  File "D:\Users\Cathmoelic\AppData\Local\Programs\Python\Python39\lib\site-packages\nbclient\client.py", line 1117, in execute
    return NotebookClient(nb=nb, resources=resources, km=km, **kwargs).execute()
  File "D:\Users\Cathmoelic\AppData\Local\Programs\Python\Python39\lib\site-packages\nbclient\util.py", line 78, in wrapped
    return just_run(coro(*args, **kwargs))
  File "D:\Users\Cathmoelic\AppData\Local\Programs\Python\Python39\lib\site-packages\nbclient\util.py", line 57, in just_run
    return loop.run_until_complete(coro)
  File "D:\Users\Cathmoelic\AppData\Local\Programs\Python\Python39\lib\asyncio\base_events.py", line 642, in run_until_complete
    return future.result()
  File "D:\Users\Cathmoelic\AppData\Local\Programs\Python\Python39\lib\site-packages\nbclient\client.py", line 558, in async_execute
    await self.async_execute_cell(
  File "D:\Users\Cathmoelic\AppData\Local\Programs\Python\Python39\lib\site-packages\nbclient\client.py", line 862, in async_execute_cell
    self._check_raise_for_error(cell, exec_reply)
  File "D:\Users\Cathmoelic\AppData\Local\Programs\Python\Python39\lib\site-packages\nbclient\client.py", line 765, in _check_raise_for_error
    raise CellExecutionError.from_cell_and_msg(cell, exec_reply_content)
nbclient.exceptions.CellExecutionError: An error occurred while executing the following cell:
------------------
%cd ..
%run utils.ipynb
%cd modal/
------------------

[1;31m---------------------------------------------------------------------------[0m
[1;31mOSError[0m                                   Traceback (most recent call last)
[1;32mD:\Users\Cathmoelic\AppData\Local\Programs\Python\Python39\lib\site-packages\IPython\core\magics\execution.py[0m in [0;36mrun[1;34m(self, parameter_s, runner, file_finder)[0m
[0;32m    702[0m             [0mfpath[0m [1;33m=[0m [0marg_lst[0m[1;33m[[0m[1;36m0[0m[1;33m][0m[1;33m[0m[1;33m[0m[0m
[1;32m--> 703[1;33m             [0mfilename[0m [1;33m=[0m [0mfile_finder[0m[1;33m([0m[0mfpath[0m[1;33m)[0m[1;33m[0m[1;33m[0m[0m
[0m[0;32m    704[0m         [1;32mexcept[0m [0mIndexError[0m[1;33m:[0m[1;33m[0m[1;33m[0m[0m

[1;32mD:\Users\Cathmoelic\AppData\Local\Programs\Python\Python39\lib\site-packages\IPython\utils\path.py[0m in [0;36mget_py_filename[1;34m(name, force_win32)[0m
[0;32m    108[0m     [1;32melse[0m[1;33m:[0m[1;33m[0m[1;33m[0m[0m
[1;32m--> 109[1;33m         [1;32mraise[0m [0mIOError[0m[1;33m([0m[1;34m'File `%r` not found.'[0m [1;33m%[0m [0mname[0m[1;33m)[0m[1;33m[0m[1;33m[0m[0m
[0m[0;32m    110[0m [1;33m[0m[0m

[1;31mOSError[0m: File `'utils.ipynb.py'` not found.

During handling of the above exception, another exception occurred:

[1;31mException[0m                                 Traceback (most recent call last)
[1;32mC:\Users\CATHMO~1\AppData\Local\Temp/ipykernel_15092/4223063063.py[0m in [0;36m<module>[1;34m[0m
[0;32m      1[0m [0mget_ipython[0m[1;33m([0m[1;33m)[0m[1;33m.[0m[0mrun_line_magic[0m[1;33m([0m[1;34m'cd'[0m[1;33m,[0m [1;34m'..'[0m[1;33m)[0m[1;33m[0m[1;33m[0m[0m
[1;32m----> 2[1;33m [0mget_ipython[0m[1;33m([0m[1;33m)[0m[1;33m.[0m[0mrun_line_magic[0m[1;33m([0m[1;34m'run'[0m[1;33m,[0m [1;34m'utils.ipynb'[0m[1;33m)[0m[1;33m[0m[1;33m[0m[0m
[0m[0;32m      3[0m [0mget_ipython[0m[1;33m([0m[1;33m)[0m[1;33m.[0m[0mrun_line_magic[0m[1;33m([0m[1;34m'cd'[0m[1;33m,[0m [1;34m'modal/'[0m[1;33m)[0m[1;33m[0m[1;33m[0m[0m

[1;32mD:\Users\Cathmoelic\AppData\Local\Programs\Python\Python39\lib\site-packages\IPython\core\interactiveshell.py[0m in [0;36mrun_line_magic[1;34m(self, magic_name, line, _stack_depth)[0m
[0;32m   2346[0m                 [0mkwargs[0m[1;33m[[0m[1;34m'local_ns'[0m[1;33m][0m [1;33m=[0m [0mself[0m[1;33m.[0m[0mget_local_scope[0m[1;33m([0m[0mstack_depth[0m[1;33m)[0m[1;33m[0m[1;33m[0m[0m
[0;32m   2347[0m             [1;32mwith[0m [0mself[0m[1;33m.[0m[0mbuiltin_trap[0m[1;33m:[0m[1;33m[0m[1;33m[0m[0m
[1;32m-> 2348[1;33m                 [0mresult[0m [1;33m=[0m [0mfn[0m[1;33m([0m[1;33m*[0m[0margs[0m[1;33m,[0m [1;33m**[0m[0mkwargs[0m[1;33m)[0m[1;33m[0m[1;33m[0m[0m
[0m[0;32m   2349[0m             [1;32mreturn[0m [0mresult[0m[1;33m[0m[1;33m[0m[0m
[0;32m   2350[0m [1;33m[0m[0m

[1;32mD:\Users\Cathmoelic\AppData\Local\Programs\Python\Python39\lib\site-packages\decorator.py[0m in [0;36mfun[1;34m(*args, **kw)[0m
[0;32m    230[0m             [1;32mif[0m [1;32mnot[0m [0mkwsyntax[0m[1;33m:[0m[1;33m[0m[1;33m[0m[0m
[0;32m    231[0m                 [0margs[0m[1;33m,[0m [0mkw[0m [1;33m=[0m [0mfix[0m[1;33m([0m[0margs[0m[1;33m,[0m [0mkw[0m[1;33m,[0m [0msig[0m[1;33m)[0m[1;33m[0m[1;33m[0m[0m
[1;32m--> 232[1;33m             [1;32mreturn[0m [0mcaller[0m[1;33m([0m[0mfunc[0m[1;33m,[0m [1;33m*[0m[1;33m([0m[0mextras[0m [1;33m+[0m [0margs[0m[1;33m)[0m[1;33m,[0m [1;33m**[0m[0mkw[0m[1;33m)[0m[1;33m[0m[1;33m[0m[0m
[0m[0;32m    233[0m     [0mfun[0m[1;33m.[0m[0m__name__[0m [1;33m=[0m [0mfunc[0m[1;33m.[0m[0m__name__[0m[1;33m[0m[1;33m[0m[0m
[0;32m    234[0m     [0mfun[0m[1;33m.[0m[0m__doc__[0m [1;33m=[0m [0mfunc[0m[1;33m.[0m[0m__doc__[0m[1;33m[0m[1;33m[0m[0m

[1;32mD:\Users\Cathmoelic\AppData\Local\Programs\Python\Python39\lib\site-packages\IPython\core\magic.py[0m in [0;36m<lambda>[1;34m(f, *a, **k)[0m
[0;32m    185[0m     [1;31m# but it's overkill for just that one bit of state.[0m[1;33m[0m[1;33m[0m[0m
[0;32m    186[0m     [1;32mdef[0m [0mmagic_deco[0m[1;33m([0m[0marg[0m[1;33m)[0m[1;33m:[0m[1;33m[0m[1;33m[0m[0m
[1;32m--> 187[1;33m         [0mcall[0m [1;33m=[0m [1;32mlambda[0m [0mf[0m[1;33m,[0m [1;33m*[0m[0ma[0m[1;33m,[0m [1;33m**[0m[0mk[0m[1;33m:[0m [0mf[0m[1;33m([0m[1;33m*[0m[0ma[0m[1;33m,[0m [1;33m**[0m[0mk[0m[1;33m)[0m[1;33m[0m[1;33m[0m[0m
[0m[0;32m    188[0m [1;33m[0m[0m
[0;32m    189[0m         [1;32mif[0m [0mcallable[0m[1;33m([0m[0marg[0m[1;33m)[0m[1;33m:[0m[1;33m[0m[1;33m[0m[0m

[1;32mD:\Users\Cathmoelic\AppData\Local\Programs\Python\Python39\lib\site-packages\IPython\core\magics\execution.py[0m in [0;36mrun[1;34m(self, parameter_s, runner, file_finder)[0m
[0;32m    712[0m             [1;32mif[0m [0mos[0m[1;33m.[0m[0mname[0m [1;33m==[0m [1;34m'nt'[0m [1;32mand[0m [0mre[0m[1;33m.[0m[0mmatch[0m[1;33m([0m[1;34mr"^'.*'$"[0m[1;33m,[0m[0mfpath[0m[1;33m)[0m[1;33m:[0m[1;33m[0m[1;33m[0m[0m
[0;32m    713[0m                 [0mwarn[0m[1;33m([0m[1;34m'For Windows, use double quotes to wrap a filename: %run "mypath\\myfile.py"'[0m[1;33m)[0m[1;33m[0m[1;33m[0m[0m
[1;32m--> 714[1;33m             [1;32mraise[0m [0mException[0m[1;33m([0m[0mmsg[0m[1;33m)[0m[1;33m[0m[1;33m[0m[0m
[0m[0;32m    715[0m         [1;32mexcept[0m [0mTypeError[0m[1;33m:[0m[1;33m[0m[1;33m[0m[0m
[0;32m    716[0m             [1;32mif[0m [0mfpath[0m [1;32min[0m [0msys[0m[1;33m.[0m[0mmeta_path[0m[1;33m:[0m[1;33m[0m[1;33m[0m[0m

[1;31mException[0m: File `'utils.ipynb.py'` not found.
Exception: File `'utils.ipynb.py'` not found.

